<sdf version='1.6'>
  <world name='default'>
    <light name='sun' type='directional'>
      <cast_shadows>1</cast_shadows>
      <pose frame=''>0 0 10 0 -0 0</pose>
      <diffuse>0.8 0.8 0.8 1</diffuse>
      <specular>0.2 0.2 0.2 1</specular>
      <attenuation>
        <range>1000</range>
        <constant>0.9</constant>
        <linear>0.01</linear>
        <quadratic>0.001</quadratic>
      </attenuation>
      <direction>-0.5 0.1 -0.9</direction>
    </light>
    <model name='ground_plane'>
      <static>1</static>
      <link name='link'>
        <collision name='collision'>
          <geometry>
            <plane>
              <normal>0 0 1</normal>
              <size>100 100</size>
            </plane>
          </geometry>
          <surface>
            <contact>
              <collide_bitmask>65535</collide_bitmask>
              <ode/>
            </contact>
            <friction>
              <ode>
                <mu>100</mu>
                <mu2>50</mu2>
              </ode>
              <torsional>
                <ode/>
              </torsional>
            </friction>
            <bounce/>
          </surface>
          <max_contacts>10</max_contacts>
        </collision>
        <visual name='visual'>
          <cast_shadows>0</cast_shadows>
          <geometry>
            <plane>
              <normal>0 0 1</normal>
              <size>100 100</size>
            </plane>
          </geometry>
          <material>
            <script>
              <uri>file://media/materials/scripts/gazebo.material</uri>
              <name>Gazebo/Grey</name>
            </script>
          </material>
        </visual>
        <self_collide>0</self_collide>
        <enable_wind>0</enable_wind>
        <kinematic>0</kinematic>
      </link>
    </model>
    <gravity>0 0 -9.8</gravity>
    <magnetic_field>6e-06 2.3e-05 -4.2e-05</magnetic_field>
    <atmosphere type='adiabatic'/>
    <physics name='default_physics' default='0' type='ode'>
      <max_step_size>0.001</max_step_size>
      <real_time_factor>1</real_time_factor>
      <real_time_update_rate>1000</real_time_update_rate>
    </physics>
    <scene>
      <ambient>0.4 0.4 0.4 1</ambient>
      <background>0.7 0.7 0.7 1</background>
      <shadows>1</shadows>
    </scene>
    <audio>
      <device>default</device>
    </audio>
    <wind/>
    <spherical_coordinates>
      <surface_model>EARTH_WGS84</surface_model>
      <latitude_deg>0</latitude_deg>
      <longitude_deg>0</longitude_deg>
      <elevation>0</elevation>
      <heading_deg>0</heading_deg>
    </spherical_coordinates>
    <model name='table'>
      <static>1</static>
      <link name='link'>
        <collision name='surface'>
          <pose frame=''>0 0 1 0 -0 0</pose>
          <geometry>
            <box>
              <size>1.5 0.8 0.03</size>
            </box>
          </geometry>
          <surface>
            <friction>
              <ode>
                <mu>0.6</mu>
                <mu2>0.6</mu2>
              </ode>
              <torsional>
                <ode/>
              </torsional>
            </friction>
            <contact>
              <ode/>
            </contact>
            <bounce/>
          </surface>
          <max_contacts>10</max_contacts>
        </collision>
        <visual name='visual1'>
          <pose frame=''>0 0 1 0 -0 0</pose>
          <geometry>
            <box>
              <size>1.5 0.8 0.03</size>
            </box>
          </geometry>
          <material>
            <script>
              <uri>file://media/materials/scripts/gazebo.material</uri>
              <name>Gazebo/Wood</name>
            </script>
          </material>
        </visual>
        <collision name='front_left_leg'>
          <pose frame=''>0.68 0.38 0.5 0 -0 0</pose>
          <geometry>
            <cylinder>
              <radius>0.02</radius>
              <length>1</length>
            </cylinder>
          </geometry>
          <max_contacts>10</max_contacts>
          <surface>
            <contact>
              <ode/>
            </contact>
            <bounce/>
            <friction>
              <torsional>
                <ode/>
              </torsional>
              <ode/>
            </friction>
          </surface>
        </collision>
        <visual name='front_left_leg'>
          <pose frame=''>0.68 0.38 0.5 0 -0 0</pose>
          <geometry>
            <cylinder>
              <radius>0.02</radius>
              <length>1</length>
            </cylinder>
          </geometry>
          <material>
            <script>
              <uri>file://media/materials/scripts/gazebo.material</uri>
              <name>Gazebo/Grey</name>
            </script>
          </material>
        </visual>
        <collision name='front_right_leg'>
          <pose frame=''>0.68 -0.38 0.5 0 -0 0</pose>
          <geometry>
            <cylinder>
              <radius>0.02</radius>
              <length>1</length>
            </cylinder>
          </geometry>
          <max_contacts>10</max_contacts>
          <surface>
            <contact>
              <ode/>
            </contact>
            <bounce/>
            <friction>
              <torsional>
                <ode/>
              </torsional>
              <ode/>
            </friction>
          </surface>
        </collision>
        <visual name='front_right_leg'>
          <pose frame=''>0.68 -0.38 0.5 0 -0 0</pose>
          <geometry>
            <cylinder>
              <radius>0.02</radius>
              <length>1</length>
            </cylinder>
          </geometry>
          <material>
            <script>
              <uri>file://media/materials/scripts/gazebo.material</uri>
              <name>Gazebo/Grey</name>
            </script>
          </material>
        </visual>
        <collision name='back_right_leg'>
          <pose frame=''>-0.68 -0.38 0.5 0 -0 0</pose>
          <geometry>
            <cylinder>
              <radius>0.02</radius>
              <length>1</length>
            </cylinder>
          </geometry>
          <max_contacts>10</max_contacts>
          <surface>
            <contact>
              <ode/>
            </contact>
            <bounce/>
            <friction>
              <torsional>
                <ode/>
              </torsional>
              <ode/>
            </friction>
          </surface>
        </collision>
        <visual name='back_right_leg'>
          <pose frame=''>-0.68 -0.38 0.5 0 -0 0</pose>
          <geometry>
            <cylinder>
              <radius>0.02</radius>
              <length>1</length>
            </cylinder>
          </geometry>
          <material>
            <script>
              <uri>file://media/materials/scripts/gazebo.material</uri>
              <name>Gazebo/Grey</name>
            </script>
          </material>
        </visual>
        <collision name='back_left_leg'>
          <pose frame=''>-0.68 0.38 0.5 0 -0 0</pose>
          <geometry>
            <cylinder>
              <radius>0.02</radius>
              <length>1</length>
            </cylinder>
          </geometry>
          <max_contacts>10</max_contacts>
          <surface>
            <contact>
              <ode/>
            </contact>
            <bounce/>
            <friction>
              <torsional>
                <ode/>
              </torsional>
              <ode/>
            </friction>
          </surface>
        </collision>
        <visual name='back_left_leg'>
          <pose frame=''>-0.68 0.38 0.5 0 -0 0</pose>
          <geometry>
            <cylinder>
              <radius>0.02</radius>
              <length>1</length>
            </cylinder>
          </geometry>
          <material>
            <script>
              <uri>file://media/materials/scripts/gazebo.material</uri>
              <name>Gazebo/Grey</name>
            </script>
          </material>
        </visual>
        <self_collide>0</self_collide>
        <enable_wind>0</enable_wind>
        <kinematic>0</kinematic>
      </link>
      <pose frame=''>0.258052 -0.027332 0 0 -0 0</pose>
    </model>
    <state world_name='default'>
      <sim_time>411 827000000</sim_time>
      <real_time>103 816928144</real_time>
      <wall_time>1614055608 578891538</wall_time>
      <iterations>56132</iterations>
      <model name='camera'>
        <pose frame=''>-0.728969 0.01318 2.27043 3.14159 1.57079 3.14159</pose>
        <scale>1 1 1</scale>
        <link name='link'>
          <pose frame=''>-0.728969 0.01318 2.27043 3.14159 1.57079 3.14159</pose>
          <velocity>0 0 0 0 -0 0</velocity>
          <acceleration>0 0 0 0 -0 0</acceleration>
          <wrench>0 0 0 0 -0 0</wrench>
        </link>
      </model>
      <model name='camera_pole'>
        <pose frame=''>-0.454487 0.691599 0.5 0 -0 0</pose>
        <scale>1 1 1</scale>
        <link name='link'>
          <pose frame=''>-0.715862 0.691599 1.2277 0 -0 0</pose>
          <velocity>0 0 0 0 -0 0</velocity>
          <acceleration>0 0 0 0 -0 0</acceleration>
          <wrench>0 0 0 0 -0 0</wrench>
        </link>
        <link name='link_0'>
          <pose frame=''>-0.718016 0.487223 2.31994 1.5708 -0 0</pose>
          <velocity>0 0 0 0 -0 0</velocity>
          <acceleration>0 0 0 0 -0 0</acceleration>
          <wrench>0 0 0 0 -0 0</wrench>
        </link>
      </model>
      <model name='edo'>
        <pose frame=''>0.008545 -0.000695 -0.000372 -0.000675 -0.007992 -6e-05</pose>
        <scale>1 1 1</scale>
        <link name='edo_base_link'>
          <pose frame=''>0.000393 -6e-06 1.0196 -0.000675 -0.007992 -6e-05</pose>
          <velocity>-0.173602 0.065119 0.197826 -3.00939 0.70231 -3.12826</velocity>
          <acceleration>0.299604 32.124 -27.8303 0.274016 -0.192067 -1.02795</acceleration>
          <wrench>0.023547 2.52476 -2.1873 0 -0 0</wrench>
        </link>
        <link name='edo_gripper_left_base_link'>
          <pose frame=''>0.323688 0.031888 1.06907 2.34563 -0.068412 -3.08807</pose>
          <velocity>0.091625 -1.18132 3.32243 -2.88191 -0.126452 -0.463291</velocity>
          <acceleration>222.363 -257.708 6322.06 -2.84959 0.94057 2.90625</acceleration>
          <wrench>0.111182 -0.128854 3.16103 0 -0 0</wrench>
        </link>
        <link name='edo_gripper_left_finger_link'>
          <pose frame=''>0.324134 0.059963 1.09762 3.04397 0.793582 -1.58697</pose>
          <velocity>-0.245127 -1.33742 3.5014 -2.88193 -0.126515 -0.463385</velocity>
          <acceleration>221.154 -234.134 6303.71 -2.7779 1.02788 2.7726</acceleration>
          <wrench>0.110577 -0.117067 3.15185 0 -0 0</wrench>
        </link>
        <link name='edo_gripper_right_base_link'>
          <pose frame=''>0.324886 -0.004041 1.03746 -0.795961 -0.068412 -3.08808</pose>
          <velocity>0.181626 -0.773565 1.71961 -2.88205 -0.126858 -0.463893</velocity>
          <acceleration>406.851 -365.878 6410.39 -2.38931 1.51024 2.05269</acceleration>
          <wrench>0.203426 -0.182939 3.20519 0 -0 0</wrench>
        </link>
        <link name='edo_gripper_right_finger_link'>
          <pose frame=''>0.321126 -0.02967 1.02372 0.097643 -0.793575 1.5546</pose>
          <velocity>0.054873 0.001716 0.233328 -2.88196 -0.126653 -0.463609</velocity>
          <acceleration>-732.506 628.939 8158.7 -2.63134 1.20806 2.46882</acceleration>
          <wrench>-0.366253 0.31447 4.07935 0 -0 0</wrench>
        </link>
        <link name='edo_link_1'>
          <pose frame=''>0.000143 8.3e-05 1.35528 -0.000713 -0.012719 -3.10672</pose>
          <velocity>-0.47925 -0.127328 -0.013425 0.171793 0.007211 0.03883</velocity>
          <acceleration>268.317 -125.414 871.642 1.7691 -1.05679 1.17062</acceleration>
          <wrench>21.0882 -9.85681 68.506 0 -0 0</wrench>
        </link>
        <link name='edo_link_2'>
          <pose frame=''>0.000289 0.000165 1.3548 -1.47969 -1.41691 -0.060894</pose>
          <velocity>-0.575567 -0.269581 -0.026691 -2.06336 0.880645 1.01049</velocity>
          <acceleration>372.404 -287.305 1469.78 2.08789 0.465814 -2.83369</acceleration>
          <wrench>29.2688 -22.5805 115.516 0 -0 0</wrench>
        </link>
        <link name='edo_link_3'>
          <pose frame=''>0.20828 0.003559 1.32094 1.58251 0.295592 0.012032</pose>
          <velocity>-0.38147 -0.503338 2.79112 2.76062 -0.139501 1.9251</velocity>
          <acceleration>249.204 -427.206 5924.09 -0.751246 0.618435 -0.528887</acceleration>
          <wrench>19.586 -33.5759 465.599 0 -0 0</wrench>
        </link>
        <link name='edo_link_4'>
          <pose frame=''>0.130086 0.002594 1.06444 3.13587 -0.295044 3.12727</pose>
          <velocity>0.379563 -2.70028 2.5619 -0.711892 0.023281 -1.40747</velocity>
          <acceleration>232.328 446.382 6114.49 0.260498 1.30998 0.734073</acceleration>
          <wrench>18.2596 35.083 480.564 0 -0 0</wrench>
        </link>
        <link name='edo_link_5'>
          <pose frame=''>0.130056 0.00414 1.06438 -3.13519 1.50225 -3.08196</pose>
          <velocity>0.374589 -2.69783 2.58523 -1.46292 0.389526 0.285703</velocity>
          <acceleration>230.415 95.5193 6182.48 3.04548 1.31012 1.80618</acceleration>
          <wrench>18.1093 7.50727 485.907 0 -0 0</wrench>
        </link>
        <link name='edo_link_6'>
          <pose frame=''>0.303953 0.013354 1.05241 1.63921 -0.010541 1.62359</pose>
          <velocity>0.31861 -1.15112 3.16133 -2.88224 -0.12713 -0.464287</velocity>
          <acceleration>228.579 -181.905 6230.4 1.10102 1.25006 -1.63586</acceleration>
          <wrench>7.53628 -5.99746 205.418 0 -0 0</wrench>
        </link>
      </model>
      <model name='ground_plane'>
        <pose frame=''>0 0 0 0 -0 0</pose>
        <scale>1 1 1</scale>
        <link name='link'>
          <pose frame=''>0 0 0 0 -0 0</pose>
          <velocity>0 0 0 0 -0 0</velocity>
          <acceleration>0 0 0 0 -0 0</acceleration>
          <wrench>0 0 0 0 -0 0</wrench>
        </link>
      </model>
      <model name='table'>
        <pose frame=''>-0.433721 -0.027332 0 0 -0 0</pose>
        <scale>1 1 1</scale>
        <link name='link'>
          <pose frame=''>-0.433721 -0.027332 0 0 -0 0</pose>
          <velocity>0 0 0 0 -0 0</velocity>
          <acceleration>0 0 0 0 -0 0</acceleration>
          <wrench>0 0 0 0 -0 0</wrench>
        </link>
      </model>
      <model name='unit_box'>
        <pose frame=''>-0.486106 0.17743 1.08848 0.042982 2e-06 -5.6e-05</pose>
        <scale>0.069598 0.069598 0.069598</scale>
        <link name='link'>
          <pose frame=''>-0.486106 0.17743 1.08848 0.042982 2e-06 -5.6e-05</pose>
          <velocity>2.5e-05 -0.00563 0.014586 0.15529 0.000674 -2.6e-05</velocity>
          <acceleration>0.049359 0.202986 18.6492 0.647177 1.36556 0.004812</acceleration>
          <wrench>0.049359 0.202986 18.6492 0 -0 0</wrench>
        </link>
      </model>
      <model name='white_plane'>
        <pose frame=''>-0.752697 -0.019956 1.03488 -3.7e-05 2e-06 0.002815</pose>
        <scale>1 1 1</scale>
        <link name='link'>
          <pose frame=''>-0.752697 -0.019956 1.03488 -3.7e-05 2e-06 0.002815</pose>
          <velocity>0 0 0 0 -0 0</velocity>
          <acceleration>0 0 0 0 -0 0</acceleration>
          <wrench>0 0 0 0 -0 0</wrench>
        </link>
      </model>
      <light name='sun'>
        <pose frame=''>0 0 10 0 -0 0</pose>
      </light>
    </state>
    <gui fullscreen='0'>
      <camera name='user_camera'>
        <pose frame=''>-5.12521 -3.74482 2.43479 0 0.298798 0.744</pose>
        <view_controller>orbit</view_controller>
        <projection_type>perspective</projection_type>
      </camera>
    </gui>
    <model name='edo'>
      <link name='edo_base_link'>
        <pose frame=''>0 0 1.02 0 -0 0</pose>
        <inertial>
          <pose frame=''>0.057188 0.005983 0.05 0 -0 0</pose>
          <mass>0.0785942</mass>
          <inertia>
            <ixx>0.0123841</ixx>
            <ixy>-0.000187985</ixy>
            <ixz>-1.32684e-06</ixz>
            <iyy>7.0169e-05</iyy>
            <iyz>-9.17417e-05</iyz>
            <izz>0.0123862</izz>
          </inertia>
        </inertial>
        <collision name='edo_base_link_collision'>
          <pose frame=''>0 0 0.135 0 -0 0</pose>
          <geometry>
            <mesh>
              <scale>1 1 1</scale>
              <uri>/home/khalid/ros/progazebo/src/eDO_description/meshes/collision/link_0.dae</uri>
            </mesh>
          </geometry>
          <surface>
            <contact>
              <ode/>
            </contact>
            <friction>
              <ode>
                <mu>0.2</mu>
                <mu2>0.2</mu2>
              </ode>
              <torsional>
                <ode/>
              </torsional>
            </friction>
            <bounce/>
          </surface>
          <max_contacts>10</max_contacts>
        </collision>
        <visual name='edo_base_link_visual'>
          <pose frame=''>0 0 0.135 0 -0 0</pose>
          <geometry>
            <mesh>
              <scale>1 1 1</scale>
              <uri>/home/khalid/ros/progazebo/src/eDO_description/meshes/visual/link_0.dae</uri>
            </mesh>
          </geometry>
          <material>
            <script>
              <uri>__default__</uri>
              <name>__default__</name>
            </script>
          </material>
        </visual>
        <gravity>1</gravity>
        <velocity_decay/>
        <self_collide>0</self_collide>
        <enable_wind>0</enable_wind>
        <kinematic>0</kinematic>
      </link>
      <joint name='world_edo_joint' type='fixed'>
        <child>edo_base_link</child>
        <parent>world</parent>
      </joint>
      <link name='edo_link_1'>
        <pose frame=''>0 0 1.357 0 -0 0</pose>
        <inertial>
          <pose frame=''>-0.037464 0.04726 0 0 -0 0</pose>
          <mass>0.0785942</mass>
          <inertia>
            <ixx>0.0123841</ixx>
            <ixy>0.000187985</ixy>
            <ixz>-1.32684e-06</ixz>
            <iyy>7.0169e-05</iyy>
            <iyz>9.17417e-05</iyz>
            <izz>0.0123862</izz>
          </inertia>
        </inertial>
        <collision name='edo_link_1_collision'>
          <pose frame=''>0 0 0 0 -0 0</pose>
          <geometry>
            <mesh>
              <scale>1 1 1</scale>
              <uri>/home/khalid/ros/progazebo/src/eDO_description/meshes/collision/link_1.dae</uri>
            </mesh>
          </geometry>
          <surface>
            <contact>
              <ode/>
            </contact>
            <friction>
              <ode>
                <mu>0.2</mu>
                <mu2>0.2</mu2>
              </ode>
              <torsional>
                <ode/>
              </torsional>
            </friction>
            <bounce/>
          </surface>
          <max_contacts>10</max_contacts>
        </collision>
        <visual name='edo_link_1_visual'>
          <pose frame=''>0 0 0 0 -0 0</pose>
          <geometry>
            <mesh>
              <scale>1 1 1</scale>
              <uri>/home/khalid/ros/progazebo/src/eDO_description/meshes/visual/link_1.dae</uri>
            </mesh>
          </geometry>
          <material>
            <script>
              <uri>__default__</uri>
              <name>__default__</name>
            </script>
          </material>
        </visual>
        <gravity>1</gravity>
        <velocity_decay/>
        <self_collide>0</self_collide>
        <enable_wind>0</enable_wind>
        <kinematic>0</kinematic>
      </link>
      <joint name='edo_joint_1' type='revolute'>
        <child>edo_link_1</child>
        <parent>edo_base_link</parent>
        <axis>
          <xyz>0 0 1</xyz>
          <limit>
            <lower>-3.10669</lower>
            <upper>3.10669</upper>
            <effort>300</effort>
            <velocity>0.5</velocity>
          </limit>
          <dynamics>
            <damping>0.5</damping>
            <friction>0</friction>
            <spring_reference>0</spring_reference>
            <spring_stiffness>0</spring_stiffness>
          </dynamics>
          <use_parent_model_frame>1</use_parent_model_frame>
        </axis>
      </joint>
      <link name='edo_link_2'>
        <pose frame=''>0 0 1.357 1.5708 -0 0</pose>
        <inertial>
          <pose frame=''>-0.016423 0.031803 -0.045948 0 -0 0</pose>
          <mass>0.0785942</mass>
          <inertia>
            <ixx>0.012207</ixx>
            <ixy>0.000930597</ixy>
            <ixz>-0.00114863</ixz>
            <iyy>0.00757607</iyy>
            <iyz>0.00593805</iyz>
            <izz>0.00505743</izz>
          </inertia>
        </inertial>
        <collision name='edo_link_2_collision'>
          <pose frame=''>0 0.2105 0 -1.5708 -0 0</pose>
          <geometry>
            <mesh>
              <scale>1 1 1</scale>
              <uri>/home/khalid/ros/progazebo/src/eDO_description/meshes/collision/link_2.dae</uri>
            </mesh>
          </geometry>
          <surface>
            <contact>
              <ode/>
            </contact>
            <friction>
              <ode>
                <mu>0.2</mu>
                <mu2>0.2</mu2>
              </ode>
              <torsional>
                <ode/>
              </torsional>
            </friction>
            <bounce/>
          </surface>
          <max_contacts>10</max_contacts>
        </collision>
        <visual name='edo_link_2_visual'>
          <pose frame=''>0 0.2105 0 -1.5708 -0 0</pose>
          <geometry>
            <mesh>
              <scale>1 1 1</scale>
              <uri>/home/khalid/ros/progazebo/src/eDO_description/meshes/visual/link_2.dae</uri>
            </mesh>
          </geometry>
          <material>
            <script>
              <uri>__default__</uri>
              <name>__default__</name>
            </script>
          </material>
        </visual>
        <gravity>1</gravity>
        <velocity_decay/>
        <self_collide>0</self_collide>
        <enable_wind>0</enable_wind>
        <kinematic>0</kinematic>
      </link>
      <joint name='edo_joint_2' type='revolute'>
        <child>edo_link_2</child>
        <parent>edo_link_1</parent>
        <axis>
          <xyz>0 1 -0</xyz>
          <limit>
            <lower>-1.71042</lower>
            <upper>1.71042</upper>
            <effort>300</effort>
            <velocity>0.5</velocity>
          </limit>
          <dynamics>
            <damping>0.5</damping>
            <friction>0</friction>
            <spring_reference>0</spring_reference>
            <spring_stiffness>0</spring_stiffness>
          </dynamics>
          <use_parent_model_frame>1</use_parent_model_frame>
        </axis>
      </joint>
      <link name='edo_link_3'>
        <pose frame=''>0 0 1.5675 -1.5708 -0 -0</pose>
        <inertial>
          <pose frame=''>-0.031475 0.0131 0.000326 0 -0 0</pose>
          <mass>0.0785942</mass>
          <inertia>
            <ixx>0.0123841</ixx>
            <ixy>0.000187985</ixy>
            <ixz>1.32684e-06</ixz>
            <iyy>7.0169e-05</iyy>
            <iyz>-9.17417e-05</iyz>
            <izz>0.0123862</izz>
          </inertia>
        </inertial>
        <collision name='edo_link_3_collision'>
          <pose frame=''>0 0 0 1.5708 -0 0</pose>
          <geometry>
            <mesh>
              <scale>1 1 1</scale>
              <uri>/home/khalid/ros/progazebo/src/eDO_description/meshes/collision/link_3.dae</uri>
            </mesh>
          </geometry>
          <surface>
            <contact>
              <ode/>
            </contact>
            <friction>
              <ode>
                <mu>0.2</mu>
                <mu2>0.2</mu2>
              </ode>
              <torsional>
                <ode/>
              </torsional>
            </friction>
            <bounce/>
          </surface>
          <max_contacts>10</max_contacts>
        </collision>
        <visual name='edo_link_3_visual'>
          <pose frame=''>0 0 0 1.5708 -0 0</pose>
          <geometry>
            <mesh>
              <scale>1 1 1</scale>
              <uri>/home/khalid/ros/progazebo/src/eDO_description/meshes/visual/link_3.dae</uri>
            </mesh>
          </geometry>
          <material>
            <script>
              <uri>__default__</uri>
              <name>__default__</name>
            </script>
          </material>
        </visual>
        <gravity>1</gravity>
        <velocity_decay/>
        <self_collide>0</self_collide>
        <enable_wind>0</enable_wind>
        <kinematic>0</kinematic>
      </link>
      <joint name='edo_joint_3' type='revolute'>
        <child>edo_link_3</child>
        <parent>edo_link_2</parent>
        <axis>
          <xyz>0 1 -0</xyz>
          <limit>
            <lower>-1.71042</lower>
            <upper>1.71042</upper>
            <effort>300</effort>
            <velocity>0.5</velocity>
          </limit>
          <dynamics>
            <damping>0.5</damping>
            <friction>0</friction>
            <spring_reference>0</spring_reference>
            <spring_stiffness>0</spring_stiffness>
          </dynamics>
          <use_parent_model_frame>1</use_parent_model_frame>
        </axis>
      </joint>
      <link name='edo_link_4'>
        <pose frame=''>-0 0 1.8355 -0 -0 -0</pose>
        <inertial>
          <pose frame=''>0.033909 0.000544 -0.013765 0 -0 0</pose>
          <mass>0.0785942</mass>
          <inertia>
            <ixx>0.0123841</ixx>
            <ixy>-1.32684e-06</ixy>
            <ixz>0.000187985</ixz>
            <iyy>0.0123862</iyy>
            <iyz>9.17417e-05</iyz>
            <izz>7.0169e-05</izz>
          </inertia>
        </inertial>
        <collision name='edo_link_4_collision'>
          <pose frame=''>0 0 0 0 -0 0</pose>
          <geometry>
            <mesh>
              <scale>1 1 1</scale>
              <uri>/home/khalid/ros/progazebo/src/eDO_description/meshes/collision/link_4.dae</uri>
            </mesh>
          </geometry>
          <surface>
            <contact>
              <ode/>
            </contact>
            <friction>
              <ode>
                <mu>0.2</mu>
                <mu2>0.2</mu2>
              </ode>
              <torsional>
                <ode/>
              </torsional>
            </friction>
            <bounce/>
          </surface>
          <max_contacts>10</max_contacts>
        </collision>
        <visual name='edo_link_4_visual'>
          <pose frame=''>0 0 0 0 -0 0</pose>
          <geometry>
            <mesh>
              <scale>1 1 1</scale>
              <uri>/home/khalid/ros/progazebo/src/eDO_description/meshes/visual/link_4.dae</uri>
            </mesh>
          </geometry>
          <material>
            <script>
              <uri>__default__</uri>
              <name>__default__</name>
            </script>
          </material>
        </visual>
        <gravity>1</gravity>
        <velocity_decay/>
        <self_collide>0</self_collide>
        <enable_wind>0</enable_wind>
        <kinematic>0</kinematic>
      </link>
      <joint name='edo_joint_4' type='revolute'>
        <child>edo_link_4</child>
        <parent>edo_link_3</parent>
        <axis>
          <xyz>-0 0 1</xyz>
          <limit>
            <lower>-3.10669</lower>
            <upper>3.10669</upper>
            <effort>300</effort>
            <velocity>0.5</velocity>
          </limit>
          <dynamics>
            <damping>0.5</damping>
            <friction>0</friction>
            <spring_reference>0</spring_reference>
            <spring_stiffness>0</spring_stiffness>
          </dynamics>
          <use_parent_model_frame>1</use_parent_model_frame>
        </axis>
      </joint>
      <link name='edo_link_5'>
        <pose frame=''>-0 0 1.8355 -0 -0 -0</pose>
        <inertial>
          <pose frame=''>0.029485 -0.000458 0.026739 0 -0 0</pose>
          <mass>0.0785942</mass>
          <inertia>
            <ixx>0.0123841</ixx>
            <ixy>1.32684e-06</ixy>
            <ixz>0.000187985</ixz>
            <iyy>0.0123862</iyy>
            <iyz>-9.17417e-05</iyz>
            <izz>7.0169e-05</izz>
          </inertia>
        </inertial>
        <collision name='edo_link_5_collision'>
          <pose frame=''>0 0 0 0 -0 0</pose>
          <geometry>
            <mesh>
              <scale>1 1 1</scale>
              <uri>/home/khalid/ros/progazebo/src/eDO_description/meshes/collision/link_5.dae</uri>
            </mesh>
          </geometry>
          <surface>
            <contact>
              <ode/>
            </contact>
            <friction>
              <ode>
                <mu>0.2</mu>
                <mu2>0.2</mu2>
              </ode>
              <torsional>
                <ode/>
              </torsional>
            </friction>
            <bounce/>
          </surface>
          <max_contacts>10</max_contacts>
        </collision>
        <visual name='edo_link_5_visual'>
          <pose frame=''>0 0 0 0 -0 0</pose>
          <geometry>
            <mesh>
              <scale>1 1 1</scale>
              <uri>/home/khalid/ros/progazebo/src/eDO_description/meshes/visual/link_5.dae</uri>
            </mesh>
          </geometry>
          <material>
            <script>
              <uri>__default__</uri>
              <name>__default__</name>
            </script>
          </material>
        </visual>
        <gravity>1</gravity>
        <velocity_decay/>
        <self_collide>0</self_collide>
        <enable_wind>0</enable_wind>
        <kinematic>0</kinematic>
      </link>
      <joint name='edo_joint_5' type='revolute'>
        <child>edo_link_5</child>
        <parent>edo_link_4</parent>
        <axis>
          <xyz>0 1 -0</xyz>
          <limit>
            <lower>-1.79769</lower>
            <upper>1.79769</upper>
            <effort>300</effort>
            <velocity>0.5</velocity>
          </limit>
          <dynamics>
            <damping>0.5</damping>
            <friction>0</friction>
            <spring_reference>0</spring_reference>
            <spring_stiffness>0</spring_stiffness>
          </dynamics>
          <use_parent_model_frame>1</use_parent_model_frame>
        </axis>
      </joint>
      <link name='edo_link_6'>
        <pose frame=''>-0 0 2.01 -0 -0 -0</pose>
        <inertial>
          <pose frame=''>6e-06 -0.007913 5e-06 0 -0 0</pose>
          <mass>0.0329702</mass>
          <inertia>
            <ixx>1.00001</ixx>
            <ixy>4.66144e-10</ixy>
            <ixz>5.32953e-09</ixz>
            <iyy>1.00001</iyy>
            <iyz>3.46334e-10</iyz>
            <izz>1.00001</izz>
          </inertia>
        </inertial>
        <collision name='edo_link_6_collision'>
          <pose frame=''>0 0 0 0 -0 0</pose>
          <geometry>
            <mesh>
              <scale>1 1 1</scale>
              <uri>/home/khalid/ros/progazebo/src/eDO_description/meshes/collision/link_6.dae</uri>
            </mesh>
          </geometry>
          <surface>
            <contact>
              <ode/>
            </contact>
            <friction>
              <ode>
                <mu>0.2</mu>
                <mu2>0.2</mu2>
              </ode>
              <torsional>
                <ode/>
              </torsional>
            </friction>
            <bounce/>
          </surface>
          <max_contacts>10</max_contacts>
        </collision>
        <collision name='edo_link_6_fixed_joint_lump__edo_gripper_link_collision_1'>
          <pose frame=''>0 0 0 0 0 -0.785398</pose>
          <geometry>
            <mesh>
              <scale>1 1 1</scale>
              <uri>/home/khalid/ros/progazebo/src/edo_gripper/meshes/base.STL</uri>
            </mesh>
          </geometry>
          <max_contacts>10</max_contacts>
          <surface>
            <contact>
              <ode/>
            </contact>
            <bounce/>
            <friction>
              <torsional>
                <ode/>
              </torsional>
              <ode/>
            </friction>
          </surface>
        </collision>
        <visual name='edo_link_6_visual'>
          <pose frame=''>0 0 0 0 -0 0</pose>
          <geometry>
            <mesh>
              <scale>1 1 1</scale>
              <uri>/home/khalid/ros/progazebo/src/eDO_description/meshes/visual/link_6.dae</uri>
            </mesh>
          </geometry>
          <material>
            <script>
              <uri>__default__</uri>
              <name>__default__</name>
            </script>
          </material>
        </visual>
        <visual name='edo_link_6_fixed_joint_lump__edo_gripper_link_visual_1'>
          <pose frame=''>0 0 0 0 0 -0.785398</pose>
          <geometry>
            <mesh>
              <scale>1 1 1</scale>
              <uri>/home/khalid/ros/progazebo/src/edo_gripper/meshes/base.STL</uri>
            </mesh>
          </geometry>
        </visual>
        <gravity>1</gravity>
        <velocity_decay/>
        <self_collide>0</self_collide>
        <enable_wind>0</enable_wind>
        <kinematic>0</kinematic>
      </link>
      <joint name='edo_joint_6' type='revolute'>
        <child>edo_link_6</child>
        <parent>edo_link_5</parent>
        <axis>
          <xyz>-0 0 1</xyz>
          <limit>
            <lower>-4.71239</lower>
            <upper>4.71239</upper>
            <effort>300</effort>
            <velocity>0.5</velocity>
          </limit>
          <dynamics>
            <damping>0.5</damping>
            <friction>0</friction>
            <spring_reference>0</spring_reference>
            <spring_stiffness>0</spring_stiffness>
          </dynamics>
          <use_parent_model_frame>1</use_parent_model_frame>
        </axis>
      </joint>
      <link name='edo_gripper_left_base_link'>
        <pose frame=''>0.017678 0.017678 2.0295 1.5708 0 0.785398</pose>
        <inertial>
          <pose frame=''>0 0 0 0 -0 0</pose>
          <mass>0.0005</mass>
          <inertia>
            <ixx>1</ixx>
            <ixy>0</ixy>
            <ixz>0</ixz>
            <iyy>1</iyy>
            <iyz>0</iyz>
            <izz>1</izz>
          </inertia>
        </inertial>
        <collision name='edo_gripper_left_base_link_collision'>
          <pose frame=''>-0.005 0 -0.04 0 -0 0</pose>
          <geometry>
            <mesh>
              <scale>1 1 1</scale>
              <uri>/home/khalid/ros/progazebo/src/edo_gripper/meshes/finger_base.STL</uri>
            </mesh>
          </geometry>
          <max_contacts>10</max_contacts>
          <surface>
            <contact>
              <ode/>
            </contact>
            <bounce/>
            <friction>
              <torsional>
                <ode/>
              </torsional>
              <ode/>
            </friction>
          </surface>
        </collision>
        <visual name='edo_gripper_left_base_link_visual'>
          <pose frame=''>-0.005 0 -0.04 0 -0 0</pose>
          <geometry>
            <mesh>
              <scale>1 1 1</scale>
              <uri>/home/khalid/ros/progazebo/src/edo_gripper/meshes/finger_base.STL</uri>
            </mesh>
          </geometry>
        </visual>
        <self_collide>0</self_collide>
        <enable_wind>0</enable_wind>
        <kinematic>0</kinematic>
      </link>
      <joint name='edo_gripper_left_base_joint' type='revolute'>
        <child>edo_gripper_left_base_link</child>
        <parent>edo_link_6</parent>
        <axis>
          <xyz>0.707107 -0.707107 0</xyz>
          <limit>
            <lower>-1.5708</lower>
            <upper>1.5708</upper>
            <effort>300</effort>
            <velocity>0.5</velocity>
          </limit>
          <dynamics>
            <damping>0.5</damping>
            <friction>0</friction>
            <spring_reference>0</spring_reference>
            <spring_stiffness>0</spring_stiffness>
          </dynamics>
          <use_parent_model_frame>1</use_parent_model_frame>
        </axis>
      </joint>
      <link name='edo_gripper_left_finger_link'>
        <pose frame=''>0.017678 0.017678 2.0695 1.5708 0 0.785398</pose>
        <inertial>
          <pose frame=''>0 0 0 0 -0 0</pose>
          <mass>0.0005</mass>
          <inertia>
            <ixx>1</ixx>
            <ixy>0</ixy>
            <ixz>0</ixz>
            <iyy>1</iyy>
            <iyz>0</iyz>
            <izz>1</izz>
          </inertia>
        </inertial>
        <collision name='edo_gripper_left_finger_link_collision'>
          <pose frame=''>-0.071 0 0 0 -0 0</pose>
          <geometry>
            <mesh>
              <scale>1 1 1</scale>
              <uri>/home/khalid/ros/progazebo/src/edo_gripper/meshes/finger_tip.STL</uri>
            </mesh>
          </geometry>
          <max_contacts>10</max_contacts>
          <surface>
            <contact>
              <ode/>
            </contact>
            <bounce/>
            <friction>
              <torsional>
                <ode/>
              </torsional>
              <ode/>
            </friction>
          </surface>
        </collision>
        <visual name='edo_gripper_left_finger_link_visual'>
          <pose frame=''>-0.071 0 0 0 -0 0</pose>
          <geometry>
            <mesh>
              <scale>1 1 1</scale>
              <uri>/home/khalid/ros/progazebo/src/edo_gripper/meshes/finger_tip.STL</uri>
            </mesh>
          </geometry>
        </visual>
        <self_collide>0</self_collide>
        <enable_wind>0</enable_wind>
        <kinematic>0</kinematic>
      </link>
      <joint name='edo_gripper_left_finger_joint' type='revolute'>
        <child>edo_gripper_left_finger_link</child>
        <parent>edo_gripper_left_base_link</parent>
        <axis>
          <xyz>0.707107 -0.707107 0</xyz>
          <limit>
            <lower>-1.5708</lower>
            <upper>1.5708</upper>
            <effort>300</effort>
            <velocity>0.5</velocity>
          </limit>
          <dynamics>
            <damping>0.5</damping>
            <friction>0</friction>
            <spring_reference>0</spring_reference>
            <spring_stiffness>0</spring_stiffness>
          </dynamics>
          <use_parent_model_frame>1</use_parent_model_frame>
        </axis>
      </joint>
      <link name='edo_gripper_right_base_link'>
        <pose frame=''>-0.017678 -0.017678 2.0295 1.5708 -0 -2.35619</pose>
        <inertial>
          <pose frame=''>0 0 0 0 -0 0</pose>
          <mass>0.0005</mass>
          <inertia>
            <ixx>1</ixx>
            <ixy>0</ixy>
            <ixz>0</ixz>
            <iyy>1</iyy>
            <iyz>0</iyz>
            <izz>1</izz>
          </inertia>
        </inertial>
        <collision name='edo_gripper_right_base_link_collision'>
          <pose frame=''>-0.005 0 -0.04 0 -0 0</pose>
          <geometry>
            <mesh>
              <scale>1 1 1</scale>
              <uri>/home/khalid/ros/progazebo/src/edo_gripper/meshes/finger_base.STL</uri>
            </mesh>
          </geometry>
          <max_contacts>10</max_contacts>
          <surface>
            <contact>
              <ode/>
            </contact>
            <bounce/>
            <friction>
              <torsional>
                <ode/>
              </torsional>
              <ode/>
            </friction>
          </surface>
        </collision>
        <visual name='edo_gripper_right_base_link_visual'>
          <pose frame=''>-0.005 0 -0.04 0 -0 0</pose>
          <geometry>
            <mesh>
              <scale>1 1 1</scale>
              <uri>/home/khalid/ros/progazebo/src/edo_gripper/meshes/finger_base.STL</uri>
            </mesh>
          </geometry>
        </visual>
        <self_collide>0</self_collide>
        <enable_wind>0</enable_wind>
        <kinematic>0</kinematic>
      </link>
      <joint name='edo_gripper_right_base_joint' type='revolute'>
        <child>edo_gripper_right_base_link</child>
        <parent>edo_link_6</parent>
        <axis>
          <xyz>-0.707107 0.707107 -0</xyz>
          <limit>
            <lower>-1.5708</lower>
            <upper>1.5708</upper>
            <effort>300</effort>
            <velocity>0.5</velocity>
          </limit>
          <dynamics>
            <damping>0.5</damping>
            <friction>0</friction>
            <spring_reference>0</spring_reference>
            <spring_stiffness>0</spring_stiffness>
          </dynamics>
          <use_parent_model_frame>1</use_parent_model_frame>
        </axis>
      </joint>
      <link name='edo_gripper_right_finger_link'>
        <pose frame=''>-0.017678 -0.017678 2.0695 1.5708 -0 -2.35619</pose>
        <inertial>
          <pose frame=''>0 0 0 0 -0 0</pose>
          <mass>0.0005</mass>
          <inertia>
            <ixx>1</ixx>
            <ixy>0</ixy>
            <ixz>0</ixz>
            <iyy>1</iyy>
            <iyz>0</iyz>
            <izz>1</izz>
          </inertia>
        </inertial>
        <collision name='edo_gripper_right_finger_link_collision'>
          <pose frame=''>-0.071 0 0 0 -0 0</pose>
          <geometry>
            <mesh>
              <scale>1 1 1</scale>
              <uri>/home/khalid/ros/progazebo/src/edo_gripper/meshes/finger_tip.STL</uri>
            </mesh>
          </geometry>
          <max_contacts>10</max_contacts>
          <surface>
            <contact>
              <ode/>
            </contact>
            <bounce/>
            <friction>
              <torsional>
                <ode/>
              </torsional>
              <ode/>
            </friction>
          </surface>
        </collision>
        <visual name='edo_gripper_right_finger_link_visual'>
          <pose frame=''>-0.071 0 0 0 -0 0</pose>
          <geometry>
            <mesh>
              <scale>1 1 1</scale>
              <uri>/home/khalid/ros/progazebo/src/edo_gripper/meshes/finger_tip.STL</uri>
            </mesh>
          </geometry>
        </visual>
        <self_collide>0</self_collide>
        <enable_wind>0</enable_wind>
        <kinematic>0</kinematic>
      </link>
      <joint name='edo_gripper_right_finger_joint' type='revolute'>
        <child>edo_gripper_right_finger_link</child>
        <parent>edo_gripper_right_base_link</parent>
        <axis>
          <xyz>-0.707107 0.707107 -0</xyz>
          <limit>
            <lower>-1.5708</lower>
            <upper>1.5708</upper>
            <effort>300</effort>
            <velocity>0.5</velocity>
          </limit>
          <dynamics>
            <damping>0.5</damping>
            <friction>0</friction>
            <spring_reference>0</spring_reference>
            <spring_stiffness>0</spring_stiffness>
          </dynamics>
          <use_parent_model_frame>1</use_parent_model_frame>
        </axis>
      </joint>
      <plugin name='gazebo_ros_control' filename='libgazebo_ros_control.so'>
        <robotNamespace>/edo</robotNamespace>
      </plugin>
      <static>0</static>
      <plugin name='gazebo_grasp_fix' filename='libgazebo_grasp_fix.so'>
        <robotNamespace>edo</robotNamespace>
        <arm>
          <arm_name>robot</arm_name>
          <palm_link>edo_link_6</palm_link>
          <gripper_link>edo_gripper_left_finger_link</gripper_link>
          <gripper_link>edo_gripper_right_finger_link</gripper_link>
        </arm>
        <forces_angle_tolerance>0</forces_angle_tolerance>
        <update_rate>16</update_rate>
        <grip_count_threshold>2</grip_count_threshold>
        <max_grip_count>3</max_grip_count>
        <release_tolerance>0.0005</release_tolerance>
        <disable_collisions_on_attach>0</disable_collisions_on_attach>
        <contact_topic>__default_topic__</contact_topic>
      </plugin>
      <pose frame=''>0 0 0 0 -0 0</pose>
    </model>
    <model name='white_plane'>
      <link name='link'>
        <inertial>
          <mass>1</mass>
          <inertia>
            <ixx>0.166667</ixx>
            <ixy>0</ixy>
            <ixz>0</ixz>
            <iyy>0.166667</iyy>
            <iyz>0</iyz>
            <izz>0.166667</izz>
          </inertia>
        </inertial>
        <self_collide>0</self_collide>
        <enable_wind>0</enable_wind>
        <kinematic>0</kinematic>
        <pose frame=''>0 0 0 0 -0 0</pose>
        <visual name='visual'>
          <geometry>
            <box>
              <size>0.722166 0.690238 0.034696</size>
            </box>
          </geometry>
          <material>
            <script>
              <name>Gazebo/Grey</name>
              <uri>file://media/materials/scripts/gazebo.material</uri>
            </script>
          </material>
          <pose frame=''>0 0 0 0 -0 0</pose>
          <transparency>0</transparency>
          <cast_shadows>1</cast_shadows>
        </visual>
        <collision name='collision'>
          <laser_retro>0</laser_retro>
          <max_contacts>10</max_contacts>
          <pose frame=''>0 0 0 0 -0 0</pose>
          <geometry>
            <box>
              <size>0.722166 0.690238 0.034696</size>
            </box>
          </geometry>
          <surface>
            <friction>
              <ode>
                <mu>1</mu>
                <mu2>1</mu2>
                <fdir1>0 0 0</fdir1>
                <slip1>0</slip1>
                <slip2>0</slip2>
              </ode>
              <torsional>
                <coefficient>1</coefficient>
                <patch_radius>0</patch_radius>
                <surface_radius>0</surface_radius>
                <use_patch_radius>1</use_patch_radius>
                <ode>
                  <slip>0</slip>
                </ode>
              </torsional>
            </friction>
            <bounce>
              <restitution_coefficient>0</restitution_coefficient>
              <threshold>1e+06</threshold>
            </bounce>
            <contact>
              <collide_without_contact>0</collide_without_contact>
              <collide_without_contact_bitmask>1</collide_without_contact_bitmask>
              <collide_bitmask>1</collide_bitmask>
              <ode>
                <soft_cfm>0</soft_cfm>
                <soft_erp>0.2</soft_erp>
                <kp>1e+13</kp>
                <kd>1</kd>
                <max_vel>0.01</max_vel>
                <min_depth>0</min_depth>
              </ode>
              <bullet>
                <split_impulse>1</split_impulse>
                <split_impulse_penetration_threshold>-0.01</split_impulse_penetration_threshold>
                <soft_cfm>0</soft_cfm>
                <soft_erp>0.2</soft_erp>
                <kp>1e+13</kp>
                <kd>1</kd>
              </bullet>
            </contact>
          </surface>
        </collision>
      </link>
      <static>1</static>
      <allow_auto_disable>1</allow_auto_disable>
      <pose frame=''>-0.723532 -0.024174 1.03234 -3.7e-05 2e-06 0.002815</pose>
    </model>
    <model name='unit_box'>
      <pose frame=''>-1.89362 -0.449376 0.5 0 -0 0</pose>
      <link name='link'>
        <inertial>
          <mass>1</mass>
          <inertia>
            <ixx>0.166667</ixx>
            <ixy>0</ixy>
            <ixz>0</ixz>
            <iyy>0.166667</iyy>
            <iyz>0</iyz>
            <izz>0.166667</izz>
          </inertia>
        </inertial>
        <collision name='collision'>
          <geometry>
            <box>
              <size>2966.25 2966.25 2966.25</size>
            </box>
          </geometry>
          <max_contacts>10</max_contacts>
          <surface>
            <contact>
              <ode/>
            </contact>
            <bounce/>
            <friction>
              <torsional>
                <ode/>
              </torsional>
              <ode/>
            </friction>
          </surface>
        </collision>
        <visual name='visual'>
          <geometry>
            <box>
              <size>2966.25 2966.25 2966.25</size>
            </box>
          </geometry>
          <material>
            <script>
              <name>Gazebo/Grey</name>
              <uri>file://media/materials/scripts/gazebo.material</uri>
            </script>
          </material>
        </visual>
        <self_collide>0</self_collide>
        <enable_wind>0</enable_wind>
        <kinematic>0</kinematic>
      </link>
    </model>
    <model name='camera_pole'>
      <link name='link'>
        <inertial>
          <mass>0.0142937</mass>
          <inertia>
            <ixx>0.00723726</ixx>
            <ixy>0</ixy>
            <ixz>0</ixz>
            <iyy>0.00723726</iyy>
            <iyz>0</iyz>
            <izz>1.05574e-05</izz>
          </inertia>
          <pose frame=''>0 0 0 0 -0 0</pose>
        </inertial>
        <self_collide>0</self_collide>
        <enable_wind>0</enable_wind>
        <kinematic>0</kinematic>
        <pose frame=''>-0.261375 0 0.727699 0 -0 0</pose>
        <visual name='visual'>
          <geometry>
            <cylinder>
              <radius>0.0384346</radius>
              <length>2.46404</length>
            </cylinder>
          </geometry>
          <material>
            <script>
              <name>Gazebo/Grey</name>
              <uri>file://media/materials/scripts/gazebo.material</uri>
            </script>
          </material>
          <pose frame=''>0 0 0 0 -0 0</pose>
          <transparency>0</transparency>
          <cast_shadows>1</cast_shadows>
        </visual>
        <collision name='collision'>
          <laser_retro>0</laser_retro>
          <max_contacts>10</max_contacts>
          <pose frame=''>0 0 0 0 -0 0</pose>
          <geometry>
            <cylinder>
              <radius>0.038435</radius>
              <length>2.46404</length>
            </cylinder>
          </geometry>
          <surface>
            <friction>
              <ode>
                <mu>1</mu>
                <mu2>1</mu2>
                <fdir1>0 0 0</fdir1>
                <slip1>0</slip1>
                <slip2>0</slip2>
              </ode>
              <torsional>
                <coefficient>1</coefficient>
                <patch_radius>0</patch_radius>
                <surface_radius>0</surface_radius>
                <use_patch_radius>1</use_patch_radius>
                <ode>
                  <slip>0</slip>
                </ode>
              </torsional>
            </friction>
            <bounce>
              <restitution_coefficient>0</restitution_coefficient>
              <threshold>1e+06</threshold>
            </bounce>
            <contact>
              <collide_without_contact>0</collide_without_contact>
              <collide_without_contact_bitmask>1</collide_without_contact_bitmask>
              <collide_bitmask>1</collide_bitmask>
              <ode>
                <soft_cfm>0</soft_cfm>
                <soft_erp>0.2</soft_erp>
                <kp>1e+13</kp>
                <kd>1</kd>
                <max_vel>0.01</max_vel>
                <min_depth>0</min_depth>
              </ode>
              <bullet>
                <split_impulse>1</split_impulse>
                <split_impulse_penetration_threshold>-0.01</split_impulse_penetration_threshold>
                <soft_cfm>0</soft_cfm>
                <soft_erp>0.2</soft_erp>
                <kp>1e+13</kp>
                <kd>1</kd>
              </bullet>
            </contact>
          </surface>
        </collision>
      </link>
      <link name='link_0'>
        <inertial>
          <mass>0.00633949</mass>
          <inertia>
            <ixx>0.000530804</ixx>
            <ixy>0</ixy>
            <ixz>0</ixz>
            <iyy>0.000530804</iyy>
            <iyz>0</iyz>
            <izz>5.02659e-06</izz>
          </inertia>
          <pose frame=''>0 0 0 0 -0 0</pose>
        </inertial>
        <pose frame=''>-0.263529 -0.204376 1.81994 1.5708 -0 0</pose>
        <visual name='visual'>
          <pose frame=''>0 0 0 0 -0 0</pose>
          <geometry>
            <cylinder>
              <radius>0.0398221</radius>
              <length>1</length>
            </cylinder>
          </geometry>
          <material>
            <lighting>1</lighting>
            <script>
              <uri>file://media/materials/scripts/gazebo.material</uri>
              <name>Gazebo/Grey</name>
            </script>
          </material>
          <transparency>0</transparency>
          <cast_shadows>1</cast_shadows>
        </visual>
        <collision name='collision'>
          <laser_retro>0</laser_retro>
          <max_contacts>10</max_contacts>
          <pose frame=''>0 0 0 0 -0 0</pose>
          <geometry>
            <cylinder>
              <radius>0.039822</radius>
              <length>1</length>
            </cylinder>
          </geometry>
          <surface>
            <friction>
              <ode>
                <mu>1</mu>
                <mu2>1</mu2>
                <fdir1>0 0 0</fdir1>
                <slip1>0</slip1>
                <slip2>0</slip2>
              </ode>
              <torsional>
                <coefficient>1</coefficient>
                <patch_radius>0</patch_radius>
                <surface_radius>0</surface_radius>
                <use_patch_radius>1</use_patch_radius>
                <ode>
                  <slip>0</slip>
                </ode>
              </torsional>
            </friction>
            <bounce>
              <restitution_coefficient>0</restitution_coefficient>
              <threshold>1e+06</threshold>
            </bounce>
            <contact>
              <collide_without_contact>0</collide_without_contact>
              <collide_without_contact_bitmask>1</collide_without_contact_bitmask>
              <collide_bitmask>1</collide_bitmask>
              <ode>
                <soft_cfm>0</soft_cfm>
                <soft_erp>0.2</soft_erp>
                <kp>1e+13</kp>
                <kd>1</kd>
                <max_vel>0.01</max_vel>
                <min_depth>0</min_depth>
              </ode>
              <bullet>
                <split_impulse>1</split_impulse>
                <split_impulse_penetration_threshold>-0.01</split_impulse_penetration_threshold>
                <soft_cfm>0</soft_cfm>
                <soft_erp>0.2</soft_erp>
                <kp>1e+13</kp>
                <kd>1</kd>
              </bullet>
            </contact>
          </surface>
        </collision>
        <self_collide>0</self_collide>
        <enable_wind>0</enable_wind>
        <kinematic>0</kinematic>
      </link>
      <static>1</static>
      <allow_auto_disable>1</allow_auto_disable>
      <pose frame=''>-0.454487 0.691599 0.5 0 -0 0</pose>
    </model>
    <model name='camera'>
      <pose frame=''>-0.6212 -0.186845 0.05 0 -0 0</pose>
      <link name='link'>
        <inertial>
          <mass>0.1</mass>
          <inertia>
            <ixx>0.000166667</ixx>
            <iyy>0.000166667</iyy>
            <izz>0.000166667</izz>
            <ixy>0</ixy>
            <ixz>0</ixz>
            <iyz>0</iyz>
          </inertia>
        </inertial>
        <collision name='collision'>
          <geometry>
            <box>
              <size>0.1 0.1 0.1</size>
            </box>
          </geometry>
          <max_contacts>10</max_contacts>
          <surface>
            <contact>
              <ode/>
            </contact>
            <bounce/>
            <friction>
              <torsional>
                <ode/>
              </torsional>
              <ode/>
            </friction>
          </surface>
        </collision>
        <visual name='visual'>
          <geometry>
            <box>
              <size>0.1 0.1 0.1</size>
            </box>
          </geometry>
        </visual>
        <sensor name='camera' type='camera'>
          <camera name='__default__'>
            <horizontal_fov>1.047</horizontal_fov>
            <image>
              <width>320</width>
              <height>240</height>
            </image>
            <clip>
              <near>0.1</near>
              <far>100</far>
            </clip>
          </camera>
          <always_on>1</always_on>
          <update_rate>30</update_rate>
          <visualize>1</visualize>
        </sensor>
        <self_collide>0</self_collide>
        <enable_wind>0</enable_wind>
        <kinematic>0</kinematic>
      </link>
    </model>
  </world>
</sdf>
